[2022-06-29 17:24:06,676][django.request.log_response():224] [ERROR] Internal Server Error: /api/project/b17df0d9f31342e28e1530675e0eaca0/
Traceback (most recent call last):
  File "C:\Users\lenovo\AppData\Local\Programs\Python\Python310\lib\site-packages\django\core\handlers\exception.py", line 47, in inner
    response = get_response(request)
  File "C:\Users\lenovo\AppData\Local\Programs\Python\Python310\lib\site-packages\django\utils\deprecation.py", line 119, in __call__
    response = self.process_response(request, response)
  File "C:\Users\lenovo\Desktop\workspace\django-controller\sse\lib\utils\middleware\middleware.py", line 88, in process_response
    self.__handle_response(request, response)
  File "C:\Users\lenovo\Desktop\workspace\django-controller\sse\lib\utils\middleware\middleware.py", line 62, in __handle_response
    if not operation_log.request_modular and settings.API_MODEL_MAP.get(request.request_path, None):
  File "C:\Users\lenovo\AppData\Local\Programs\Python\Python310\lib\site-packages\django\conf\__init__.py", line 83, in __getattr__
    val = getattr(self._wrapped, name)
AttributeError: 'Settings' object has no attribute 'API_MODEL_MAP'
[2022-06-29 17:24:06,678][django.server.log_message():161] [ERROR] "PUT /api/project/b17df0d9f31342e28e1530675e0eaca0/ HTTP/1.1" 500 94177
[2022-06-29 17:24:06,865][django.request.log_response():224] [ERROR] Internal Server Error: /api/project/b17df0d9f31342e28e1530675e0eaca0/
Traceback (most recent call last):
  File "C:\Users\lenovo\AppData\Local\Programs\Python\Python310\lib\site-packages\django\core\handlers\exception.py", line 47, in inner
    response = get_response(request)
  File "C:\Users\lenovo\AppData\Local\Programs\Python\Python310\lib\site-packages\django\utils\deprecation.py", line 119, in __call__
    response = self.process_response(request, response)
  File "C:\Users\lenovo\Desktop\workspace\django-controller\sse\lib\utils\middleware\middleware.py", line 88, in process_response
    self.__handle_response(request, response)
  File "C:\Users\lenovo\Desktop\workspace\django-controller\sse\lib\utils\middleware\middleware.py", line 62, in __handle_response
    if not operation_log.request_modular and settings.API_MODEL_MAP.get(request.request_path, None):
  File "C:\Users\lenovo\AppData\Local\Programs\Python\Python310\lib\site-packages\django\conf\__init__.py", line 83, in __getattr__
    val = getattr(self._wrapped, name)
AttributeError: 'Settings' object has no attribute 'API_MODEL_MAP'
[2022-06-29 17:24:06,867][django.server.log_message():161] [ERROR] "PUT /api/project/b17df0d9f31342e28e1530675e0eaca0/ HTTP/1.1" 500 94177
[2022-06-29 17:27:28,547][django.request.log_response():224] [ERROR] Internal Server Error: /user/login/
Traceback (most recent call last):
  File "C:\Users\lenovo\AppData\Local\Programs\Python\Python310\lib\site-packages\django\db\models\query.py", line 581, in get_or_create
    return self.get(**kwargs), False
  File "C:\Users\lenovo\AppData\Local\Programs\Python\Python310\lib\site-packages\django\db\models\query.py", line 435, in get
    raise self.model.DoesNotExist(
public.models.OperationLog.DoesNotExist: OperationLog matching query does not exist.

During handling of the above exception, another exception occurred:

Traceback (most recent call last):
  File "C:\Users\lenovo\AppData\Local\Programs\Python\Python310\lib\site-packages\django\core\handlers\exception.py", line 47, in inner
    response = get_response(request)
  File "C:\Users\lenovo\AppData\Local\Programs\Python\Python310\lib\site-packages\django\utils\deprecation.py", line 119, in __call__
    response = self.process_response(request, response)
  File "C:\Users\lenovo\Desktop\workspace\django-controller\sse\lib\utils\middleware\middleware.py", line 88, in process_response
    self.__handle_response(request, response)
  File "C:\Users\lenovo\Desktop\workspace\django-controller\sse\lib\utils\middleware\middleware.py", line 61, in __handle_response
    operation_log, creat = OperationLog.objects.update_or_create(defaults=info, id=self.operation_log_id)
  File "C:\Users\lenovo\AppData\Local\Programs\Python\Python310\lib\site-packages\django\db\models\manager.py", line 85, in manager_method
    return getattr(self.get_queryset(), name)(*args, **kwargs)
  File "C:\Users\lenovo\AppData\Local\Programs\Python\Python310\lib\site-packages\django\db\models\query.py", line 608, in update_or_create
    obj, created = self.select_for_update().get_or_create(defaults, **kwargs)
  File "C:\Users\lenovo\AppData\Local\Programs\Python\Python310\lib\site-packages\django\db\models\query.py", line 583, in get_or_create
    params = self._extract_model_params(defaults, **kwargs)
  File "C:\Users\lenovo\AppData\Local\Programs\Python\Python310\lib\site-packages\django\db\models\query.py", line 634, in _extract_model_params
    raise exceptions.FieldError(
django.core.exceptions.FieldError: Invalid field name(s) for model OperationLog: 'dept_belong_id'.
[2022-06-29 17:27:28,550][django.server.log_message():161] [ERROR] "POST /user/login/ HTTP/1.1" 500 110508
[2022-06-29 17:27:33,530][django.request.log_response():224] [ERROR] Internal Server Error: /user/login/
Traceback (most recent call last):
  File "C:\Users\lenovo\AppData\Local\Programs\Python\Python310\lib\site-packages\django\db\models\query.py", line 581, in get_or_create
    return self.get(**kwargs), False
  File "C:\Users\lenovo\AppData\Local\Programs\Python\Python310\lib\site-packages\django\db\models\query.py", line 435, in get
    raise self.model.DoesNotExist(
public.models.OperationLog.DoesNotExist: OperationLog matching query does not exist.

During handling of the above exception, another exception occurred:

Traceback (most recent call last):
  File "C:\Users\lenovo\AppData\Local\Programs\Python\Python310\lib\site-packages\django\core\handlers\exception.py", line 47, in inner
    response = get_response(request)
  File "C:\Users\lenovo\AppData\Local\Programs\Python\Python310\lib\site-packages\django\utils\deprecation.py", line 119, in __call__
    response = self.process_response(request, response)
  File "C:\Users\lenovo\Desktop\workspace\django-controller\sse\lib\utils\middleware\middleware.py", line 88, in process_response
    self.__handle_response(request, response)
  File "C:\Users\lenovo\Desktop\workspace\django-controller\sse\lib\utils\middleware\middleware.py", line 61, in __handle_response
    operation_log, creat = OperationLog.objects.update_or_create(defaults=info, id=self.operation_log_id)
  File "C:\Users\lenovo\AppData\Local\Programs\Python\Python310\lib\site-packages\django\db\models\manager.py", line 85, in manager_method
    return getattr(self.get_queryset(), name)(*args, **kwargs)
  File "C:\Users\lenovo\AppData\Local\Programs\Python\Python310\lib\site-packages\django\db\models\query.py", line 608, in update_or_create
    obj, created = self.select_for_update().get_or_create(defaults, **kwargs)
  File "C:\Users\lenovo\AppData\Local\Programs\Python\Python310\lib\site-packages\django\db\models\query.py", line 583, in get_or_create
    params = self._extract_model_params(defaults, **kwargs)
  File "C:\Users\lenovo\AppData\Local\Programs\Python\Python310\lib\site-packages\django\db\models\query.py", line 634, in _extract_model_params
    raise exceptions.FieldError(
django.core.exceptions.FieldError: Invalid field name(s) for model OperationLog: 'dept_belong_id'.
[2022-06-29 17:27:33,533][django.server.log_message():161] [ERROR] "POST /user/login/ HTTP/1.1" 500 110508
[2022-06-29 17:28:21,344][django.request.log_response():224] [ERROR] Internal Server Error: /user/login/
Traceback (most recent call last):
  File "C:\Users\lenovo\AppData\Local\Programs\Python\Python310\lib\site-packages\django\db\models\query.py", line 581, in get_or_create
    return self.get(**kwargs), False
  File "C:\Users\lenovo\AppData\Local\Programs\Python\Python310\lib\site-packages\django\db\models\query.py", line 435, in get
    raise self.model.DoesNotExist(
public.models.OperationLog.DoesNotExist: OperationLog matching query does not exist.

During handling of the above exception, another exception occurred:

Traceback (most recent call last):
  File "C:\Users\lenovo\AppData\Local\Programs\Python\Python310\lib\site-packages\django\core\handlers\exception.py", line 47, in inner
    response = get_response(request)
  File "C:\Users\lenovo\AppData\Local\Programs\Python\Python310\lib\site-packages\django\utils\deprecation.py", line 119, in __call__
    response = self.process_response(request, response)
  File "C:\Users\lenovo\Desktop\workspace\django-controller\sse\lib\utils\middleware\middleware.py", line 88, in process_response
    self.__handle_response(request, response)
  File "C:\Users\lenovo\Desktop\workspace\django-controller\sse\lib\utils\middleware\middleware.py", line 61, in __handle_response
    operation_log, creat = OperationLog.objects.update_or_create(defaults=info, id=self.operation_log_id)
  File "C:\Users\lenovo\AppData\Local\Programs\Python\Python310\lib\site-packages\django\db\models\manager.py", line 85, in manager_method
    return getattr(self.get_queryset(), name)(*args, **kwargs)
  File "C:\Users\lenovo\AppData\Local\Programs\Python\Python310\lib\site-packages\django\db\models\query.py", line 608, in update_or_create
    obj, created = self.select_for_update().get_or_create(defaults, **kwargs)
  File "C:\Users\lenovo\AppData\Local\Programs\Python\Python310\lib\site-packages\django\db\models\query.py", line 583, in get_or_create
    params = self._extract_model_params(defaults, **kwargs)
  File "C:\Users\lenovo\AppData\Local\Programs\Python\Python310\lib\site-packages\django\db\models\query.py", line 634, in _extract_model_params
    raise exceptions.FieldError(
django.core.exceptions.FieldError: Invalid field name(s) for model OperationLog: 'dept_belong_id'.
[2022-06-29 17:28:21,347][django.server.log_message():161] [ERROR] "POST /user/login/ HTTP/1.1" 500 110508
[2022-06-29 17:54:34,503][sse.lib.utils.logger.__init__():20] [ERROR] An error occurred:{'msg': '登录失败', 'result': False, 'code': 1003, 'error': '请求报文校验不通过，密码填写错误'}
[2022-06-29 17:55:17,267][sse.lib.utils.logger.__init__():20] [ERROR] An error occurred:{'msg': '登录失败', 'result': False, 'code': 1003, 'error': '请求报文校验不通过，密码填写错误'}
[2022-06-29 17:55:21,001][django.request.log_response():224] [ERROR] Internal Server Error: /user/login/
Traceback (most recent call last):
  File "C:\Users\lenovo\AppData\Local\Programs\Python\Python310\lib\site-packages\rest_framework\views.py", line 497, in dispatch
    self.initial(request, *args, **kwargs)
  File "C:\Users\lenovo\AppData\Local\Programs\Python\Python310\lib\site-packages\rest_framework\views.py", line 416, in initial
    self.check_throttles(request)
  File "C:\Users\lenovo\AppData\Local\Programs\Python\Python310\lib\site-packages\rest_framework\views.py", line 371, in check_throttles
    self.throttled(request, duration)
  File "C:\Users\lenovo\AppData\Local\Programs\Python\Python310\lib\site-packages\rest_framework\views.py", line 181, in throttled
    raise exceptions.Throttled(wait)
rest_framework.exceptions.Throttled: 请求超过了限速。 Expected available in 6 seconds.

During handling of the above exception, another exception occurred:

Traceback (most recent call last):
  File "C:\Users\lenovo\AppData\Local\Programs\Python\Python310\lib\site-packages\rest_framework\settings.py", line 177, in import_from_string
    return import_string(val)
  File "C:\Users\lenovo\AppData\Local\Programs\Python\Python310\lib\site-packages\django\utils\module_loading.py", line 17, in import_string
    module = import_module(module_path)
  File "C:\Users\lenovo\AppData\Local\Programs\Python\Python310\lib\importlib\__init__.py", line 126, in import_module
    return _bootstrap._gcd_import(name[level:], package, level)
  File "<frozen importlib._bootstrap>", line 1050, in _gcd_import
  File "<frozen importlib._bootstrap>", line 1027, in _find_and_load
  File "<frozen importlib._bootstrap>", line 1004, in _find_and_load_unlocked
ModuleNotFoundError: No module named 'sse.lib.utils.exceptions'

During handling of the above exception, another exception occurred:

Traceback (most recent call last):
  File "C:\Users\lenovo\AppData\Local\Programs\Python\Python310\lib\site-packages\django\core\handlers\exception.py", line 47, in inner
    response = get_response(request)
  File "C:\Users\lenovo\AppData\Local\Programs\Python\Python310\lib\site-packages\django\core\handlers\base.py", line 181, in _get_response
    response = wrapped_callback(request, *callback_args, **callback_kwargs)
  File "C:\Users\lenovo\AppData\Local\Programs\Python\Python310\lib\site-packages\django\views\decorators\csrf.py", line 54, in wrapped_view
    return view_func(*args, **kwargs)
  File "C:\Users\lenovo\AppData\Local\Programs\Python\Python310\lib\site-packages\rest_framework\viewsets.py", line 125, in view
    return self.dispatch(request, *args, **kwargs)
  File "C:\Users\lenovo\AppData\Local\Programs\Python\Python310\lib\site-packages\rest_framework\views.py", line 509, in dispatch
    response = self.handle_exception(exc)
  File "C:\Users\lenovo\AppData\Local\Programs\Python\Python310\lib\site-packages\rest_framework\views.py", line 463, in handle_exception
    exception_handler = self.get_exception_handler()
  File "C:\Users\lenovo\AppData\Local\Programs\Python\Python310\lib\site-packages\rest_framework\views.py", line 298, in get_exception_handler
    return self.settings.EXCEPTION_HANDLER
  File "C:\Users\lenovo\AppData\Local\Programs\Python\Python310\lib\site-packages\rest_framework\settings.py", line 225, in __getattr__
    val = perform_import(val, attr)
  File "C:\Users\lenovo\AppData\Local\Programs\Python\Python310\lib\site-packages\rest_framework\settings.py", line 166, in perform_import
    return import_from_string(val, setting_name)
  File "C:\Users\lenovo\AppData\Local\Programs\Python\Python310\lib\site-packages\rest_framework\settings.py", line 180, in import_from_string
    raise ImportError(msg)
ImportError: Could not import 'sse.lib.utils.exceptions.CustomExceptionHandler' for API setting 'EXCEPTION_HANDLER'. ModuleNotFoundError: No module named 'sse.lib.utils.exceptions'.
[2022-06-29 17:55:21,005][django.server.log_message():161] [ERROR] "POST /user/login/ HTTP/1.1" 500 141468
[2022-06-29 17:55:25,629][django.request.log_response():224] [ERROR] Internal Server Error: /user/login/
Traceback (most recent call last):
  File "C:\Users\lenovo\AppData\Local\Programs\Python\Python310\lib\site-packages\rest_framework\views.py", line 497, in dispatch
    self.initial(request, *args, **kwargs)
  File "C:\Users\lenovo\AppData\Local\Programs\Python\Python310\lib\site-packages\rest_framework\views.py", line 416, in initial
    self.check_throttles(request)
  File "C:\Users\lenovo\AppData\Local\Programs\Python\Python310\lib\site-packages\rest_framework\views.py", line 371, in check_throttles
    self.throttled(request, duration)
  File "C:\Users\lenovo\AppData\Local\Programs\Python\Python310\lib\site-packages\rest_framework\views.py", line 181, in throttled
    raise exceptions.Throttled(wait)
rest_framework.exceptions.Throttled: 请求超过了限速。 Expected available in 1 second.

During handling of the above exception, another exception occurred:

Traceback (most recent call last):
  File "C:\Users\lenovo\AppData\Local\Programs\Python\Python310\lib\site-packages\rest_framework\settings.py", line 177, in import_from_string
    return import_string(val)
  File "C:\Users\lenovo\AppData\Local\Programs\Python\Python310\lib\site-packages\django\utils\module_loading.py", line 17, in import_string
    module = import_module(module_path)
  File "C:\Users\lenovo\AppData\Local\Programs\Python\Python310\lib\importlib\__init__.py", line 126, in import_module
    return _bootstrap._gcd_import(name[level:], package, level)
  File "<frozen importlib._bootstrap>", line 1050, in _gcd_import
  File "<frozen importlib._bootstrap>", line 1027, in _find_and_load
  File "<frozen importlib._bootstrap>", line 1004, in _find_and_load_unlocked
ModuleNotFoundError: No module named 'sse.lib.utils.exceptions'

During handling of the above exception, another exception occurred:

Traceback (most recent call last):
  File "C:\Users\lenovo\AppData\Local\Programs\Python\Python310\lib\site-packages\django\core\handlers\exception.py", line 47, in inner
    response = get_response(request)
  File "C:\Users\lenovo\AppData\Local\Programs\Python\Python310\lib\site-packages\django\core\handlers\base.py", line 181, in _get_response
    response = wrapped_callback(request, *callback_args, **callback_kwargs)
  File "C:\Users\lenovo\AppData\Local\Programs\Python\Python310\lib\site-packages\django\views\decorators\csrf.py", line 54, in wrapped_view
    return view_func(*args, **kwargs)
  File "C:\Users\lenovo\AppData\Local\Programs\Python\Python310\lib\site-packages\rest_framework\viewsets.py", line 125, in view
    return self.dispatch(request, *args, **kwargs)
  File "C:\Users\lenovo\AppData\Local\Programs\Python\Python310\lib\site-packages\rest_framework\views.py", line 509, in dispatch
    response = self.handle_exception(exc)
  File "C:\Users\lenovo\AppData\Local\Programs\Python\Python310\lib\site-packages\rest_framework\views.py", line 463, in handle_exception
    exception_handler = self.get_exception_handler()
  File "C:\Users\lenovo\AppData\Local\Programs\Python\Python310\lib\site-packages\rest_framework\views.py", line 298, in get_exception_handler
    return self.settings.EXCEPTION_HANDLER
  File "C:\Users\lenovo\AppData\Local\Programs\Python\Python310\lib\site-packages\rest_framework\settings.py", line 225, in __getattr__
    val = perform_import(val, attr)
  File "C:\Users\lenovo\AppData\Local\Programs\Python\Python310\lib\site-packages\rest_framework\settings.py", line 166, in perform_import
    return import_from_string(val, setting_name)
  File "C:\Users\lenovo\AppData\Local\Programs\Python\Python310\lib\site-packages\rest_framework\settings.py", line 180, in import_from_string
    raise ImportError(msg)
ImportError: Could not import 'sse.lib.utils.exceptions.CustomExceptionHandler' for API setting 'EXCEPTION_HANDLER'. ModuleNotFoundError: No module named 'sse.lib.utils.exceptions'.
[2022-06-29 17:55:25,635][django.server.log_message():161] [ERROR] "POST /user/login/ HTTP/1.1" 500 141466
[2022-06-29 17:55:45,360][django.request.log_response():224] [ERROR] Internal Server Error: /api/scenario/9dc6ad3b71fc425f8ff7fd49de20284f/
Traceback (most recent call last):
  File "C:\Users\lenovo\AppData\Local\Programs\Python\Python310\lib\site-packages\rest_framework\views.py", line 506, in dispatch
    response = handler(request, *args, **kwargs)
  File "C:\Users\lenovo\Desktop\workspace\django-controller\sse\lib\core\model_view_set.py", line 19, in update
    response = super().update(request, *args, **kwargs)
  File "C:\Users\lenovo\AppData\Local\Programs\Python\Python310\lib\site-packages\rest_framework\mixins.py", line 68, in update
    self.perform_update(serializer)
  File "C:\Users\lenovo\AppData\Local\Programs\Python\Python310\lib\site-packages\rest_framework\mixins.py", line 78, in perform_update
    serializer.save()
  File "C:\Users\lenovo\AppData\Local\Programs\Python\Python310\lib\site-packages\rest_framework\serializers.py", line 200, in save
    self.instance = self.update(self.instance, validated_data)
  File "C:\Users\lenovo\Desktop\workspace\django-controller\sse\applications\api\model_serializer.py", line 68, in update
    field = param["field"] + "@" + str(param["type"])
TypeError: string indices must be integers

During handling of the above exception, another exception occurred:

Traceback (most recent call last):
  File "C:\Users\lenovo\AppData\Local\Programs\Python\Python310\lib\site-packages\rest_framework\settings.py", line 177, in import_from_string
    return import_string(val)
  File "C:\Users\lenovo\AppData\Local\Programs\Python\Python310\lib\site-packages\django\utils\module_loading.py", line 17, in import_string
    module = import_module(module_path)
  File "C:\Users\lenovo\AppData\Local\Programs\Python\Python310\lib\importlib\__init__.py", line 126, in import_module
    return _bootstrap._gcd_import(name[level:], package, level)
  File "<frozen importlib._bootstrap>", line 1050, in _gcd_import
  File "<frozen importlib._bootstrap>", line 1027, in _find_and_load
  File "<frozen importlib._bootstrap>", line 1004, in _find_and_load_unlocked
ModuleNotFoundError: No module named 'sse.lib.utils.exceptions'

During handling of the above exception, another exception occurred:

Traceback (most recent call last):
  File "C:\Users\lenovo\AppData\Local\Programs\Python\Python310\lib\site-packages\django\core\handlers\exception.py", line 47, in inner
    response = get_response(request)
  File "C:\Users\lenovo\AppData\Local\Programs\Python\Python310\lib\site-packages\django\core\handlers\base.py", line 181, in _get_response
    response = wrapped_callback(request, *callback_args, **callback_kwargs)
  File "C:\Users\lenovo\AppData\Local\Programs\Python\Python310\lib\site-packages\django\views\decorators\csrf.py", line 54, in wrapped_view
    return view_func(*args, **kwargs)
  File "C:\Users\lenovo\AppData\Local\Programs\Python\Python310\lib\site-packages\rest_framework\viewsets.py", line 125, in view
    return self.dispatch(request, *args, **kwargs)
  File "C:\Users\lenovo\AppData\Local\Programs\Python\Python310\lib\site-packages\rest_framework\views.py", line 509, in dispatch
    response = self.handle_exception(exc)
  File "C:\Users\lenovo\AppData\Local\Programs\Python\Python310\lib\site-packages\rest_framework\views.py", line 463, in handle_exception
    exception_handler = self.get_exception_handler()
  File "C:\Users\lenovo\AppData\Local\Programs\Python\Python310\lib\site-packages\rest_framework\views.py", line 298, in get_exception_handler
    return self.settings.EXCEPTION_HANDLER
  File "C:\Users\lenovo\AppData\Local\Programs\Python\Python310\lib\site-packages\rest_framework\settings.py", line 225, in __getattr__
    val = perform_import(val, attr)
  File "C:\Users\lenovo\AppData\Local\Programs\Python\Python310\lib\site-packages\rest_framework\settings.py", line 166, in perform_import
    return import_from_string(val, setting_name)
  File "C:\Users\lenovo\AppData\Local\Programs\Python\Python310\lib\site-packages\rest_framework\settings.py", line 180, in import_from_string
    raise ImportError(msg)
ImportError: Could not import 'sse.lib.utils.exceptions.CustomExceptionHandler' for API setting 'EXCEPTION_HANDLER'. ModuleNotFoundError: No module named 'sse.lib.utils.exceptions'.
[2022-06-29 17:55:45,364][django.server.log_message():161] [ERROR] "PUT /api/scenario/9dc6ad3b71fc425f8ff7fd49de20284f/ HTTP/1.1" 500 162605
[2022-06-29 17:55:52,084][django.request.log_response():224] [ERROR] Internal Server Error: /api/scenario/9dc6ad3b71fc425f8ff7fd49de20284f/
Traceback (most recent call last):
  File "C:\Users\lenovo\AppData\Local\Programs\Python\Python310\lib\site-packages\rest_framework\views.py", line 506, in dispatch
    response = handler(request, *args, **kwargs)
  File "C:\Users\lenovo\Desktop\workspace\django-controller\sse\lib\core\model_view_set.py", line 19, in update
    response = super().update(request, *args, **kwargs)
  File "C:\Users\lenovo\AppData\Local\Programs\Python\Python310\lib\site-packages\rest_framework\mixins.py", line 68, in update
    self.perform_update(serializer)
  File "C:\Users\lenovo\AppData\Local\Programs\Python\Python310\lib\site-packages\rest_framework\mixins.py", line 78, in perform_update
    serializer.save()
  File "C:\Users\lenovo\AppData\Local\Programs\Python\Python310\lib\site-packages\rest_framework\serializers.py", line 200, in save
    self.instance = self.update(self.instance, validated_data)
  File "C:\Users\lenovo\Desktop\workspace\django-controller\sse\applications\api\model_serializer.py", line 68, in update
    field = param["field"] + "@" + str(param["type"])
TypeError: string indices must be integers

During handling of the above exception, another exception occurred:

Traceback (most recent call last):
  File "C:\Users\lenovo\AppData\Local\Programs\Python\Python310\lib\site-packages\rest_framework\settings.py", line 177, in import_from_string
    return import_string(val)
  File "C:\Users\lenovo\AppData\Local\Programs\Python\Python310\lib\site-packages\django\utils\module_loading.py", line 17, in import_string
    module = import_module(module_path)
  File "C:\Users\lenovo\AppData\Local\Programs\Python\Python310\lib\importlib\__init__.py", line 126, in import_module
    return _bootstrap._gcd_import(name[level:], package, level)
  File "<frozen importlib._bootstrap>", line 1050, in _gcd_import
  File "<frozen importlib._bootstrap>", line 1027, in _find_and_load
  File "<frozen importlib._bootstrap>", line 1004, in _find_and_load_unlocked
ModuleNotFoundError: No module named 'sse.lib.utils.exceptions'

During handling of the above exception, another exception occurred:

Traceback (most recent call last):
  File "C:\Users\lenovo\AppData\Local\Programs\Python\Python310\lib\site-packages\django\core\handlers\exception.py", line 47, in inner
    response = get_response(request)
  File "C:\Users\lenovo\AppData\Local\Programs\Python\Python310\lib\site-packages\django\core\handlers\base.py", line 181, in _get_response
    response = wrapped_callback(request, *callback_args, **callback_kwargs)
  File "C:\Users\lenovo\AppData\Local\Programs\Python\Python310\lib\site-packages\django\views\decorators\csrf.py", line 54, in wrapped_view
    return view_func(*args, **kwargs)
  File "C:\Users\lenovo\AppData\Local\Programs\Python\Python310\lib\site-packages\rest_framework\viewsets.py", line 125, in view
    return self.dispatch(request, *args, **kwargs)
  File "C:\Users\lenovo\AppData\Local\Programs\Python\Python310\lib\site-packages\rest_framework\views.py", line 509, in dispatch
    response = self.handle_exception(exc)
  File "C:\Users\lenovo\AppData\Local\Programs\Python\Python310\lib\site-packages\rest_framework\views.py", line 463, in handle_exception
    exception_handler = self.get_exception_handler()
  File "C:\Users\lenovo\AppData\Local\Programs\Python\Python310\lib\site-packages\rest_framework\views.py", line 298, in get_exception_handler
    return self.settings.EXCEPTION_HANDLER
  File "C:\Users\lenovo\AppData\Local\Programs\Python\Python310\lib\site-packages\rest_framework\settings.py", line 225, in __getattr__
    val = perform_import(val, attr)
  File "C:\Users\lenovo\AppData\Local\Programs\Python\Python310\lib\site-packages\rest_framework\settings.py", line 166, in perform_import
    return import_from_string(val, setting_name)
  File "C:\Users\lenovo\AppData\Local\Programs\Python\Python310\lib\site-packages\rest_framework\settings.py", line 180, in import_from_string
    raise ImportError(msg)
ImportError: Could not import 'sse.lib.utils.exceptions.CustomExceptionHandler' for API setting 'EXCEPTION_HANDLER'. ModuleNotFoundError: No module named 'sse.lib.utils.exceptions'.
[2022-06-29 17:55:52,088][django.server.log_message():161] [ERROR] "PUT /api/scenario/9dc6ad3b71fc425f8ff7fd49de20284f/ HTTP/1.1" 500 162605
[2022-06-29 17:56:35,203][sse.lib.core.exceptions.CustomExceptionHandler():116] [ERROR] Traceback (most recent call last):
  File "C:\Users\lenovo\AppData\Local\Programs\Python\Python310\lib\site-packages\rest_framework\views.py", line 506, in dispatch
    response = handler(request, *args, **kwargs)
  File "C:\Users\lenovo\Desktop\workspace\django-controller\sse\lib\core\model_view_set.py", line 19, in update
    response = super().update(request, *args, **kwargs)
  File "C:\Users\lenovo\AppData\Local\Programs\Python\Python310\lib\site-packages\rest_framework\mixins.py", line 68, in update
    self.perform_update(serializer)
  File "C:\Users\lenovo\AppData\Local\Programs\Python\Python310\lib\site-packages\rest_framework\mixins.py", line 78, in perform_update
    serializer.save()
  File "C:\Users\lenovo\AppData\Local\Programs\Python\Python310\lib\site-packages\rest_framework\serializers.py", line 200, in save
    self.instance = self.update(self.instance, validated_data)
  File "C:\Users\lenovo\Desktop\workspace\django-controller\sse\applications\api\model_serializer.py", line 68, in update
    field = param["field"] + "@" + str(param["type"])
TypeError: string indices must be integers

[2022-06-29 17:56:36,530][sse.lib.core.exceptions.CustomExceptionHandler():116] [ERROR] Traceback (most recent call last):
  File "C:\Users\lenovo\AppData\Local\Programs\Python\Python310\lib\site-packages\rest_framework\views.py", line 506, in dispatch
    response = handler(request, *args, **kwargs)
  File "C:\Users\lenovo\Desktop\workspace\django-controller\sse\lib\core\model_view_set.py", line 19, in update
    response = super().update(request, *args, **kwargs)
  File "C:\Users\lenovo\AppData\Local\Programs\Python\Python310\lib\site-packages\rest_framework\mixins.py", line 68, in update
    self.perform_update(serializer)
  File "C:\Users\lenovo\AppData\Local\Programs\Python\Python310\lib\site-packages\rest_framework\mixins.py", line 78, in perform_update
    serializer.save()
  File "C:\Users\lenovo\AppData\Local\Programs\Python\Python310\lib\site-packages\rest_framework\serializers.py", line 200, in save
    self.instance = self.update(self.instance, validated_data)
  File "C:\Users\lenovo\Desktop\workspace\django-controller\sse\applications\api\model_serializer.py", line 68, in update
    field = param["field"] + "@" + str(param["type"])
TypeError: string indices must be integers

[2022-06-29 18:01:26,973][sse.lib.core.exceptions.CustomExceptionHandler():116] [ERROR] Traceback (most recent call last):
  File "C:\Users\lenovo\AppData\Local\Programs\Python\Python310\lib\site-packages\rest_framework\views.py", line 506, in dispatch
    response = handler(request, *args, **kwargs)
  File "C:\Users\lenovo\Desktop\workspace\django-controller\sse\lib\core\model_view_set.py", line 19, in update
    response = super().update(request, *args, **kwargs)
  File "C:\Users\lenovo\AppData\Local\Programs\Python\Python310\lib\site-packages\rest_framework\mixins.py", line 68, in update
    self.perform_update(serializer)
  File "C:\Users\lenovo\AppData\Local\Programs\Python\Python310\lib\site-packages\rest_framework\mixins.py", line 78, in perform_update
    serializer.save()
  File "C:\Users\lenovo\AppData\Local\Programs\Python\Python310\lib\site-packages\rest_framework\serializers.py", line 200, in save
    self.instance = self.update(self.instance, validated_data)
  File "C:\Users\lenovo\Desktop\workspace\django-controller\sse\applications\api\model_serializer.py", line 68, in update
    field = param["field"] + "@" + str(param["type"])
TypeError: string indices must be integers

[2022-06-29 18:01:30,589][sse.lib.core.exceptions.CustomExceptionHandler():116] [ERROR] Traceback (most recent call last):
  File "C:\Users\lenovo\AppData\Local\Programs\Python\Python310\lib\site-packages\rest_framework\views.py", line 506, in dispatch
    response = handler(request, *args, **kwargs)
  File "C:\Users\lenovo\Desktop\workspace\django-controller\sse\lib\core\model_view_set.py", line 19, in update
    response = super().update(request, *args, **kwargs)
  File "C:\Users\lenovo\AppData\Local\Programs\Python\Python310\lib\site-packages\rest_framework\mixins.py", line 68, in update
    self.perform_update(serializer)
  File "C:\Users\lenovo\AppData\Local\Programs\Python\Python310\lib\site-packages\rest_framework\mixins.py", line 78, in perform_update
    serializer.save()
  File "C:\Users\lenovo\AppData\Local\Programs\Python\Python310\lib\site-packages\rest_framework\serializers.py", line 200, in save
    self.instance = self.update(self.instance, validated_data)
  File "C:\Users\lenovo\Desktop\workspace\django-controller\sse\applications\api\model_serializer.py", line 68, in update
    field = param["field"] + "@" + str(param["type"])
TypeError: string indices must be integers

[2022-06-30 12:10:46,593][sse.lib.core.exceptions.CustomExceptionHandler():116] [ERROR] Traceback (most recent call last):
  File "C:\Users\lenovo\AppData\Local\Programs\Python\Python310\lib\site-packages\django\shortcuts.py", line 76, in get_object_or_404
    return queryset.get(*args, **kwargs)
  File "C:\Users\lenovo\AppData\Local\Programs\Python\Python310\lib\site-packages\django\db\models\query.py", line 435, in get
    raise self.model.DoesNotExist(
api.models.Project.DoesNotExist: Project matching query does not exist.

During handling of the above exception, another exception occurred:

Traceback (most recent call last):
  File "C:\Users\lenovo\AppData\Local\Programs\Python\Python310\lib\site-packages\rest_framework\views.py", line 506, in dispatch
    response = handler(request, *args, **kwargs)
  File "C:\Users\lenovo\Desktop\workspace\django-controller\sse\lib\core\model_view_set.py", line 15, in retrieve
    response = super().retrieve(request, *args, **kwargs)
  File "C:\Users\lenovo\AppData\Local\Programs\Python\Python310\lib\site-packages\rest_framework\mixins.py", line 54, in retrieve
    instance = self.get_object()
  File "C:\Users\lenovo\AppData\Local\Programs\Python\Python310\lib\site-packages\rest_framework\generics.py", line 96, in get_object
    obj = get_object_or_404(queryset, **filter_kwargs)
  File "C:\Users\lenovo\AppData\Local\Programs\Python\Python310\lib\site-packages\rest_framework\generics.py", line 19, in get_object_or_404
    return _get_object_or_404(queryset, *filter_args, **filter_kwargs)
  File "C:\Users\lenovo\AppData\Local\Programs\Python\Python310\lib\site-packages\django\shortcuts.py", line 78, in get_object_or_404
    raise Http404('No %s matches the given query.' % queryset.model._meta.object_name)
django.http.response.Http404: No Project matches the given query.

[2022-06-30 12:10:54,443][sse.lib.core.exceptions.CustomExceptionHandler():116] [ERROR] Traceback (most recent call last):
  File "C:\Users\lenovo\AppData\Local\Programs\Python\Python310\lib\site-packages\django\shortcuts.py", line 76, in get_object_or_404
    return queryset.get(*args, **kwargs)
  File "C:\Users\lenovo\AppData\Local\Programs\Python\Python310\lib\site-packages\django\db\models\query.py", line 435, in get
    raise self.model.DoesNotExist(
api.models.Project.DoesNotExist: Project matching query does not exist.

During handling of the above exception, another exception occurred:

Traceback (most recent call last):
  File "C:\Users\lenovo\AppData\Local\Programs\Python\Python310\lib\site-packages\rest_framework\views.py", line 506, in dispatch
    response = handler(request, *args, **kwargs)
  File "C:\Users\lenovo\Desktop\workspace\django-controller\sse\lib\core\model_view_set.py", line 15, in retrieve
    response = super().retrieve(request, *args, **kwargs)
  File "C:\Users\lenovo\AppData\Local\Programs\Python\Python310\lib\site-packages\rest_framework\mixins.py", line 54, in retrieve
    instance = self.get_object()
  File "C:\Users\lenovo\AppData\Local\Programs\Python\Python310\lib\site-packages\rest_framework\generics.py", line 96, in get_object
    obj = get_object_or_404(queryset, **filter_kwargs)
  File "C:\Users\lenovo\AppData\Local\Programs\Python\Python310\lib\site-packages\rest_framework\generics.py", line 19, in get_object_or_404
    return _get_object_or_404(queryset, *filter_args, **filter_kwargs)
  File "C:\Users\lenovo\AppData\Local\Programs\Python\Python310\lib\site-packages\django\shortcuts.py", line 78, in get_object_or_404
    raise Http404('No %s matches the given query.' % queryset.model._meta.object_name)
django.http.response.Http404: No Project matches the given query.

[2022-06-30 13:10:37,995][django.request.log_response():224] [ERROR] Internal Server Error: /api/execute/
Traceback (most recent call last):
  File "C:\Users\lenovo\AppData\Local\Programs\Python\Python310\lib\site-packages\django\core\handlers\exception.py", line 47, in inner
    response = get_response(request)
  File "C:\Users\lenovo\AppData\Local\Programs\Python\Python310\lib\site-packages\django\core\handlers\base.py", line 181, in _get_response
    response = wrapped_callback(request, *callback_args, **callback_kwargs)
  File "C:\Users\lenovo\AppData\Local\Programs\Python\Python310\lib\site-packages\django\views\decorators\csrf.py", line 54, in wrapped_view
    return view_func(*args, **kwargs)
  File "C:\Users\lenovo\Desktop\workspace\django-controller\sse\applications\api\views.py", line 152, in execute
    celery_exec_request.delay(message)
  File "C:\Users\lenovo\AppData\Local\Programs\Python\Python310\lib\site-packages\celery\app\task.py", line 425, in delay
    return self.apply_async(args, kwargs)
  File "C:\Users\lenovo\AppData\Local\Programs\Python\Python310\lib\site-packages\celery\app\task.py", line 575, in apply_async
    return app.send_task(
  File "C:\Users\lenovo\AppData\Local\Programs\Python\Python310\lib\site-packages\celery\app\base.py", line 784, in send_task
    with self.producer_or_acquire(producer) as P:
  File "C:\Users\lenovo\AppData\Local\Programs\Python\Python310\lib\site-packages\celery\app\base.py", line 919, in producer_or_acquire
    producer, self.producer_pool.acquire, block=True,
  File "C:\Users\lenovo\AppData\Local\Programs\Python\Python310\lib\site-packages\celery\app\base.py", line 1303, in producer_pool
    return self.amqp.producer_pool
  File "C:\Users\lenovo\AppData\Local\Programs\Python\Python310\lib\site-packages\celery\app\amqp.py", line 583, in producer_pool
    self.app.connection_for_write()]
  File "C:\Users\lenovo\AppData\Local\Programs\Python\Python310\lib\site-packages\celery\app\base.py", line 816, in connection_for_write
    return self._connection(url or self.conf.broker_write_url, **kwargs)
  File "C:\Users\lenovo\AppData\Local\Programs\Python\Python310\lib\site-packages\celery\app\base.py", line 867, in _connection
    return self.amqp.Connection(
  File "C:\Users\lenovo\AppData\Local\Programs\Python\Python310\lib\site-packages\kombu\connection.py", line 181, in __init__
    if not get_transport_cls(transport).can_parse_url:
  File "C:\Users\lenovo\AppData\Local\Programs\Python\Python310\lib\site-packages\kombu\transport\__init__.py", line 85, in get_transport_cls
    _transport_cache[transport] = resolve_transport(transport)
  File "C:\Users\lenovo\AppData\Local\Programs\Python\Python310\lib\site-packages\kombu\transport\__init__.py", line 70, in resolve_transport
    return symbol_by_name(transport)
  File "C:\Users\lenovo\AppData\Local\Programs\Python\Python310\lib\site-packages\kombu\utils\imports.py", line 56, in symbol_by_name
    module = imp(module_name, package=package, **kwargs)
  File "C:\Users\lenovo\AppData\Local\Programs\Python\Python310\lib\importlib\__init__.py", line 126, in import_module
    return _bootstrap._gcd_import(name[level:], package, level)
  File "<frozen importlib._bootstrap>", line 1050, in _gcd_import
  File "<frozen importlib._bootstrap>", line 1027, in _find_and_load
  File "<frozen importlib._bootstrap>", line 1006, in _find_and_load_unlocked
  File "<frozen importlib._bootstrap>", line 688, in _load_unlocked
  File "<frozen importlib._bootstrap_external>", line 883, in exec_module
  File "<frozen importlib._bootstrap>", line 241, in _call_with_frames_removed
  File "C:\Users\lenovo\AppData\Local\Programs\Python\Python310\lib\site-packages\kombu\transport\redis.py", line 262, in <module>
    class PrefixedStrictRedis(GlobalKeyPrefixMixin, redis.Redis):
AttributeError: 'NoneType' object has no attribute 'Redis'
[2022-06-30 13:10:37,999][django.server.log_message():161] [ERROR] "POST /api/execute/ HTTP/1.1" 500 219040
[2022-06-30 15:12:05,015][sse.lib.core.exceptions.CustomExceptionHandler():116] [ERROR] Traceback (most recent call last):
  File "C:\Users\lenovo\AppData\Local\Programs\Python\Python310\lib\site-packages\django\shortcuts.py", line 76, in get_object_or_404
    return queryset.get(*args, **kwargs)
  File "C:\Users\lenovo\AppData\Local\Programs\Python\Python310\lib\site-packages\django\db\models\query.py", line 435, in get
    raise self.model.DoesNotExist(
api.models.Project.DoesNotExist: Project matching query does not exist.

During handling of the above exception, another exception occurred:

Traceback (most recent call last):
  File "C:\Users\lenovo\AppData\Local\Programs\Python\Python310\lib\site-packages\rest_framework\views.py", line 506, in dispatch
    response = handler(request, *args, **kwargs)
  File "C:\Users\lenovo\Desktop\workspace\django-controller\sse\lib\core\model_view_set.py", line 15, in retrieve
    response = super().retrieve(request, *args, **kwargs)
  File "C:\Users\lenovo\AppData\Local\Programs\Python\Python310\lib\site-packages\rest_framework\mixins.py", line 54, in retrieve
    instance = self.get_object()
  File "C:\Users\lenovo\AppData\Local\Programs\Python\Python310\lib\site-packages\rest_framework\generics.py", line 96, in get_object
    obj = get_object_or_404(queryset, **filter_kwargs)
  File "C:\Users\lenovo\AppData\Local\Programs\Python\Python310\lib\site-packages\rest_framework\generics.py", line 19, in get_object_or_404
    return _get_object_or_404(queryset, *filter_args, **filter_kwargs)
  File "C:\Users\lenovo\AppData\Local\Programs\Python\Python310\lib\site-packages\django\shortcuts.py", line 78, in get_object_or_404
    raise Http404('No %s matches the given query.' % queryset.model._meta.object_name)
django.http.response.Http404: No Project matches the given query.

[2022-06-30 15:16:16,139][sse.lib.core.exceptions.CustomExceptionHandler():116] [ERROR] Traceback (most recent call last):
  File "C:\Users\lenovo\AppData\Local\Programs\Python\Python310\lib\site-packages\django\shortcuts.py", line 76, in get_object_or_404
    return queryset.get(*args, **kwargs)
  File "C:\Users\lenovo\AppData\Local\Programs\Python\Python310\lib\site-packages\django\db\models\query.py", line 435, in get
    raise self.model.DoesNotExist(
api.models.Project.DoesNotExist: Project matching query does not exist.

During handling of the above exception, another exception occurred:

Traceback (most recent call last):
  File "C:\Users\lenovo\AppData\Local\Programs\Python\Python310\lib\site-packages\rest_framework\views.py", line 506, in dispatch
    response = handler(request, *args, **kwargs)
  File "C:\Users\lenovo\Desktop\workspace\django-controller\sse\lib\core\model_view_set.py", line 15, in retrieve
    response = super().retrieve(request, *args, **kwargs)
  File "C:\Users\lenovo\AppData\Local\Programs\Python\Python310\lib\site-packages\rest_framework\mixins.py", line 54, in retrieve
    instance = self.get_object()
  File "C:\Users\lenovo\AppData\Local\Programs\Python\Python310\lib\site-packages\rest_framework\generics.py", line 96, in get_object
    obj = get_object_or_404(queryset, **filter_kwargs)
  File "C:\Users\lenovo\AppData\Local\Programs\Python\Python310\lib\site-packages\rest_framework\generics.py", line 19, in get_object_or_404
    return _get_object_or_404(queryset, *filter_args, **filter_kwargs)
  File "C:\Users\lenovo\AppData\Local\Programs\Python\Python310\lib\site-packages\django\shortcuts.py", line 78, in get_object_or_404
    raise Http404('No %s matches the given query.' % queryset.model._meta.object_name)
django.http.response.Http404: No Project matches the given query.

[2022-06-30 15:39:58,487][sse.lib.core.exceptions.CustomExceptionHandler():116] [ERROR] Traceback (most recent call last):
  File "C:\Users\lenovo\AppData\Local\Programs\Python\Python310\lib\site-packages\django\shortcuts.py", line 76, in get_object_or_404
    return queryset.get(*args, **kwargs)
  File "C:\Users\lenovo\AppData\Local\Programs\Python\Python310\lib\site-packages\django\db\models\query.py", line 435, in get
    raise self.model.DoesNotExist(
api.models.Project.DoesNotExist: Project matching query does not exist.

During handling of the above exception, another exception occurred:

Traceback (most recent call last):
  File "C:\Users\lenovo\AppData\Local\Programs\Python\Python310\lib\site-packages\rest_framework\views.py", line 506, in dispatch
    response = handler(request, *args, **kwargs)
  File "C:\Users\lenovo\Desktop\workspace\django-controller\sse\lib\core\model_view_set.py", line 15, in retrieve
    response = super().retrieve(request, *args, **kwargs)
  File "C:\Users\lenovo\AppData\Local\Programs\Python\Python310\lib\site-packages\rest_framework\mixins.py", line 54, in retrieve
    instance = self.get_object()
  File "C:\Users\lenovo\AppData\Local\Programs\Python\Python310\lib\site-packages\rest_framework\generics.py", line 96, in get_object
    obj = get_object_or_404(queryset, **filter_kwargs)
  File "C:\Users\lenovo\AppData\Local\Programs\Python\Python310\lib\site-packages\rest_framework\generics.py", line 19, in get_object_or_404
    return _get_object_or_404(queryset, *filter_args, **filter_kwargs)
  File "C:\Users\lenovo\AppData\Local\Programs\Python\Python310\lib\site-packages\django\shortcuts.py", line 78, in get_object_or_404
    raise Http404('No %s matches the given query.' % queryset.model._meta.object_name)
django.http.response.Http404: No Project matches the given query.

[2022-06-30 17:25:54,324][sse.lib.core.exceptions.CustomExceptionHandler():116] [ERROR] Traceback (most recent call last):
  File "C:\Users\lenovo\AppData\Local\Programs\Python\Python310\lib\site-packages\rest_framework\views.py", line 506, in dispatch
    response = handler(request, *args, **kwargs)
  File "C:\Users\lenovo\Desktop\workspace\django-controller\sse\lib\core\model_view_set.py", line 19, in update
    response = super().update(request, *args, **kwargs)
  File "C:\Users\lenovo\AppData\Local\Programs\Python\Python310\lib\site-packages\rest_framework\mixins.py", line 68, in update
    self.perform_update(serializer)
  File "C:\Users\lenovo\AppData\Local\Programs\Python\Python310\lib\site-packages\rest_framework\mixins.py", line 78, in perform_update
    serializer.save()
  File "C:\Users\lenovo\AppData\Local\Programs\Python\Python310\lib\site-packages\rest_framework\serializers.py", line 200, in save
    self.instance = self.update(self.instance, validated_data)
  File "C:\Users\lenovo\Desktop\workspace\django-controller\sse\applications\api\model_serializer.py", line 68, in update
    field = param["field"] + "@" + str(param["type"])
TypeError: string indices must be integers

[2022-06-30 17:25:55,563][sse.lib.core.exceptions.CustomExceptionHandler():116] [ERROR] Traceback (most recent call last):
  File "C:\Users\lenovo\AppData\Local\Programs\Python\Python310\lib\site-packages\rest_framework\views.py", line 506, in dispatch
    response = handler(request, *args, **kwargs)
  File "C:\Users\lenovo\Desktop\workspace\django-controller\sse\lib\core\model_view_set.py", line 19, in update
    response = super().update(request, *args, **kwargs)
  File "C:\Users\lenovo\AppData\Local\Programs\Python\Python310\lib\site-packages\rest_framework\mixins.py", line 68, in update
    self.perform_update(serializer)
  File "C:\Users\lenovo\AppData\Local\Programs\Python\Python310\lib\site-packages\rest_framework\mixins.py", line 78, in perform_update
    serializer.save()
  File "C:\Users\lenovo\AppData\Local\Programs\Python\Python310\lib\site-packages\rest_framework\serializers.py", line 200, in save
    self.instance = self.update(self.instance, validated_data)
  File "C:\Users\lenovo\Desktop\workspace\django-controller\sse\applications\api\model_serializer.py", line 68, in update
    field = param["field"] + "@" + str(param["type"])
TypeError: string indices must be integers

[2022-06-30 17:25:57,127][sse.lib.core.exceptions.CustomExceptionHandler():116] [ERROR] Traceback (most recent call last):
  File "C:\Users\lenovo\AppData\Local\Programs\Python\Python310\lib\site-packages\rest_framework\views.py", line 506, in dispatch
    response = handler(request, *args, **kwargs)
  File "C:\Users\lenovo\Desktop\workspace\django-controller\sse\lib\core\model_view_set.py", line 19, in update
    response = super().update(request, *args, **kwargs)
  File "C:\Users\lenovo\AppData\Local\Programs\Python\Python310\lib\site-packages\rest_framework\mixins.py", line 68, in update
    self.perform_update(serializer)
  File "C:\Users\lenovo\AppData\Local\Programs\Python\Python310\lib\site-packages\rest_framework\mixins.py", line 78, in perform_update
    serializer.save()
  File "C:\Users\lenovo\AppData\Local\Programs\Python\Python310\lib\site-packages\rest_framework\serializers.py", line 200, in save
    self.instance = self.update(self.instance, validated_data)
  File "C:\Users\lenovo\Desktop\workspace\django-controller\sse\applications\api\model_serializer.py", line 68, in update
    field = param["field"] + "@" + str(param["type"])
TypeError: string indices must be integers

[2022-06-30 17:25:59,181][sse.lib.core.exceptions.CustomExceptionHandler():116] [ERROR] Traceback (most recent call last):
  File "C:\Users\lenovo\AppData\Local\Programs\Python\Python310\lib\site-packages\rest_framework\views.py", line 506, in dispatch
    response = handler(request, *args, **kwargs)
  File "C:\Users\lenovo\Desktop\workspace\django-controller\sse\lib\core\model_view_set.py", line 19, in update
    response = super().update(request, *args, **kwargs)
  File "C:\Users\lenovo\AppData\Local\Programs\Python\Python310\lib\site-packages\rest_framework\mixins.py", line 68, in update
    self.perform_update(serializer)
  File "C:\Users\lenovo\AppData\Local\Programs\Python\Python310\lib\site-packages\rest_framework\mixins.py", line 78, in perform_update
    serializer.save()
  File "C:\Users\lenovo\AppData\Local\Programs\Python\Python310\lib\site-packages\rest_framework\serializers.py", line 200, in save
    self.instance = self.update(self.instance, validated_data)
  File "C:\Users\lenovo\Desktop\workspace\django-controller\sse\applications\api\model_serializer.py", line 68, in update
    field = param["field"] + "@" + str(param["type"])
TypeError: string indices must be integers

[2022-07-01 17:52:46,481][sse.lib.utils.logger.execute():149] [ERROR] Fail to parser data,due to error:['“”的值有一个错误的日期格式。它的格式应该是YYYY-MM-DD HH:MM[:ss[.uuuuuu]][TZ] ']
[2022-07-01 17:54:52,753][sse.lib.utils.logger.execute():149] [ERROR] Fail to parser data,due to error:['“”的值有一个错误的日期格式。它的格式应该是YYYY-MM-DD HH:MM[:ss[.uuuuuu]][TZ] ']
[2022-07-01 18:01:48,210][sse.lib.utils.logger.execute():149] [ERROR] Fail to parser data,due to error:['“”的值有一个错误的日期格式。它的格式应该是YYYY-MM-DD HH:MM[:ss[.uuuuuu]][TZ] ']
[2022-07-01 18:04:44,708][sse.lib.utils.logger.execute():149] [ERROR] Fail to parser data,due to error:['“”的值有一个错误的日期格式。它的格式应该是YYYY-MM-DD HH:MM[:ss[.uuuuuu]][TZ] ']
[2022-07-01 18:07:21,307][django.request.log_response():224] [ERROR] Internal Server Error: /api/execute/
Traceback (most recent call last):
  File "C:\Users\lenovo\AppData\Local\Programs\Python\Python310\lib\site-packages\django\core\handlers\exception.py", line 47, in inner
    response = get_response(request)
  File "C:\Users\lenovo\AppData\Local\Programs\Python\Python310\lib\site-packages\django\core\handlers\base.py", line 181, in _get_response
    response = wrapped_callback(request, *callback_args, **callback_kwargs)
  File "C:\Users\lenovo\AppData\Local\Programs\Python\Python310\lib\site-packages\django\views\decorators\csrf.py", line 54, in wrapped_view
    return view_func(*args, **kwargs)
  File "C:\Users\lenovo\Desktop\workspace\django-controller\sse\applications\api\views.py", line 160, in execute
    type_="轮询任务:周期"+setting["interval"]
TypeError: can only concatenate str (not "int") to str
[2022-07-01 18:07:21,309][django.server.log_message():161] [ERROR] "POST /api/execute/ HTTP/1.1" 500 98659
